Workbook

Sheet Cleaned Data
A1: Sector | B1: Year | C1: Month | D1: Cereals and products | E1: Meat and fish | F1: Egg | G1: Milk and products | H1: Oils and fats | I1: Fruits | J1: Vegetables | K1: Pulses and products | L1: Sugar and Confectionery | M1: Spices | N1: Non-alcoholic beverages | O1: Prepared meals, snacks, sweets, etc. | P1: Food and beverages | Q1: Pan, tobacco, and intoxicants | R1: Clothing | S1: Footwear | T1: Clothing and footwear | U1: Housing | V1: Fuel and light | W1: Household goods and services | X1: Health | Y1: Transport and communication | Z1: Recreation and amusement | AA1: Education | AB1: Personal care and effects | AC1: Miscellaneous | AD1: General index
A2: Broader Category | D2: Basic Food Items | E2: Basic Food Items | F2: Basic Food Items | G2: Basic Food Items | H2: Basic Food Items | I2: Basic Food Items | J2: Basic Food Items | K2: Basic Food Items | L2: Other Food and Intoxicants | M2: Basic Food Items | N2: Other Food and Intoxicants | O2: Other Food and Intoxicants | P2: Other Food and Intoxicants | Q2: Other Food and Intoxicants | R2: Clothing and footwear | S2: Clothing and footwear | T2: Clothing and footwear | U2: Housing and Utilities | V2: Housing and Utilities | W2: Housing and Utilities | X2: Services and Miscellaneous | Y2: Services and Miscellaneous | Z2: Services and Miscellaneous | AA2: Services and Miscellaneous | AB2: Services and Miscellaneous | AC2: Services and Miscellaneous
A3: Rural | B3: 2013 | C3: January | D3: 107.5 | E3: 106.3 | F3: 108.1 | G3: 104.9 | H3: 106.1 | I3: 103.9 | J3: 101.9 | K3: 106.1 | L3: 106.8 | M3: 103.1 | N3: 104.8 | O3: 106.7 | P3: 105.5 | Q3: 105.1 | R3: 106.5 | S3: 105.8 | T3: 106.4 | U3: NA | V3: 105.5 | W3: 104.8 | X3: 104 | Y3: 103.3 | Z3: 103.4 | AA3: 103.8 | AB3: 104.7 | AC3: 104 | AD3: 105.1
A4: Urban | B4: 2013 | C4: January | D4: 110.5 | E4: 109.1 | F4: 113 | G4: 103.6 | H4: 103.4 | I4: 102.3 | J4: 102.9 | K4: 105.8 | L4: 105.1 | M4: 101.8 | N4: 105.1 | O4: 107.9 | P4: 105.9 | Q4: 105.2 | R4: 105.9 | S4: 105 | T4: 105.8 | U4: 100.3 | V4: 105.4 | W4: 104.8 | X4: 104.1 | Y4: 103.2 | Z4: 102.9 | AA4: 103.5 | AB4: 104.3 | AC4: 103.7 | AD4: 104
A5: Rural+Urban | B5: 2013 | C5: January | D5: 108.4 | E5: 107.3 | F5: 110 | G5: 104.4 | H5: 105.1 | I5: 103.2 | J5: 102.2 | K5: 106 | L5: 106.2 | M5: 102.7 | N5: 104.9 | O5: 107.3 | P5: 105.6 | Q5: 105.1 | R5: 106.3 | S5: 105.5 | T5: 106.2 | U5: 100.3 | V5: 105.5 | W5: 104.8 | X5: 104 | Y5: 103.2 | Z5: 103.1 | AA5: 103.6 | AB5: 104.5 | AC5: 103.9 | AD5: 104.6
A6: Rural | B6: 2013 | C6: February | D6: 109.2 | E6: 108.7 | F6: 110.2 | G6: 105.4 | H6: 106.7 | I6: 104 | J6: 102.4 | K6: 105.9 | L6: 105.7 | M6: 103.1 | N6: 105.1 | O6: 107.7 | P6: 106.3 | Q6: 105.6 | R6: 107.1 | S6: 106.3 | T6: 107 | U6: NA | V6: 106.2 | W6: 105.2 | X6: 104.4 | Y6: 103.9 | Z6: 104 | AA6: 104.1 | AB6: 104.6 | AC6: 104.4 | AD6: 105.8
A7: Urban | B7: 2013 | C7: February | D7: 112.9 | E7: 112.9 | F7: 116.9 | G7: 104 | H7: 103.5 | I7: 103.1 | J7: 104.9 | K7: 104.1 | L7: 103.8 | M7: 102.3 | N7: 106 | O7: 109 | P7: 107.2 | Q7: 106 | R7: 106.6 | S7: 105.5 | T7: 106.4 | U7: 100.4 | V7: 105.7 | W7: 105.2 | X7: 104.7 | Y7: 104.4 | Z7: 103.3 | AA7: 103.7 | AB7: 104.3 | AC7: 104.3 | AD7: 104.7
A8: Rural+Urban | B8: 2013 | C8: February | D8: 110.4 | E8: 110.2 | F8: 112.8 | G8: 104.9 | H8: 105.5 | I8: 103.6 | J8: 103.2 | K8: 105.3 | L8: 105.1 | M8: 102.8 | N8: 105.5 | O8: 108.3 | P8: 106.6 | Q8: 105.7 | R8: 106.9 | S8: 106 | T8: 106.8 | U8: 100.4 | V8: 106 | W8: 105.2 | X8: 104.5 | Y8: 104.2 | Z8: 103.6 | AA8: 103.9 | AB8: 104.5 | AC8: 104.4 | AD8: 105.3
A9: Rural | B9: 2013 | C9: March | D9: 110.2 | E9: 108.8 | F9: 109.9 | G9: 105.6 | H9: 106.2 | I9: 105.7 | J9: 101.4 | K9: 105.7 | L9: 105 | M9: 103.3 | N9: 105.6 | O9: 108.2 | P9: 106.6 | Q9: 106.5 | R9: 107.6 | S9: 106.8 | T9: 107.5 | U9: NA | V9: 106.1 | W9: 105.6 | X9: 104.7 | Y9: 104.6 | Z9: 104 | AA9: 104.3 | AB9: 104.3 | AC9: 104.6 | AD9: 106
A10: Urban | B10: 2013 | C10: March | D10: 113.9 | E10: 111.4 | F10: 113.2 | G10: 104.3 | H10: 102.7 | I10: 104.9 | J10: 103.8 | K10: 103.5 | L10: 102.6 | M10: 102.4 | N10: 107 | O10: 109.8 | P10: 107.3 | Q10: 106.8 | R10: 107.2 | S10: 106 | T10: 107 | U10: 100.4 | V10: 106 | W10: 105.7 | X10: 105.2 | Y10: 105.5 | Z10: 103.5 | AA10: 103.8 | AB10: 104.2 | AC10: 104.9 | AD10: 105
A11: Rural+Urban | B11: 2013 | C11: March | D11: 111.4 | E11: 109.7 | F11: 111.2 | G11: 105.1 | H11: 104.9 | I11: 105.3 | J11: 102.2 | K11: 105 | L11: 104.2 | M11: 103 | N11: 106.2 | O11: 108.9 | P11: 106.9 | Q11: 106.6 | R11: 107.4 | S11: 106.5 | T11: 107.3 | U11: 100.4 | V11: 106.1 | W11: 105.6 | X11: 104.9 | Y11: 105.1 | Z11: 103.7 | AA11: 104 | AB11: 104.3 | AC11: 104.7 | AD11: 105.5
A12: Rural | B12: 2013 | C12: April | D12: 110.2 | E12: 109.5 | F12: 106.9 | G12: 106.3 | H12: 105.7 | I12: 108.3 | J12: 103.4 | K12: 105.7 | L12: 104.2 | M12: 103.2 | N12: 106.5 | O12: 108.8 | P12: 107.1 | Q12: 107.1 | R12: 108.1 | S12: 107.4 | T12: 108 | U12: NA | V12: 106.5 | W12: 106.1 | X12: 105.1 | Y12: 104.4 | Z12: 104.5 | AA12: 104.8 | AB12: 102.7 | AC12: 104.6 | AD12: 106.4
A13: Urban | B13: 2013 | C13: April | D13: 114.6 | E13: 113.4 | F13: 106 | G13: 104.7 | H13: 102.1 | I13: 109.5 | J13: 109.7 | K13: 104.6 | L13: 102 | M13: 103.5 | N13: 108.2 | O13: 110.6 | P13: 108.8 | Q13: 108.5 | R13: 107.9 | S13: 106.4 | T13: 107.7 | U13: 100.5 | V13: 106.4 | W13: 106.5 | X13: 105.7 | Y13: 105 | Z13: 104 | AA13: 105.2 | AB13: 103.2 | AC13: 105.1 | AD13: 105.7
A14: Rural+Urban | B14: 2013 | C14: April | D14: 111.6 | E14: 110.9 | F14: 106.6 | G14: 105.7 | H14: 104.4 | I14: 108.9 | J14: 105.5 | K14: 105.3 | L14: 103.5 | M14: 103.3 | N14: 107.2 | O14: 109.6 | P14: 107.7 | Q14: 107.5 | R14: 108 | S14: 107 | T14: 107.9 | U14: 100.5 | V14: 106.5 | W14: 106.3 | X14: 105.3 | Y14: 104.7 | Z14: 104.2 | AA14: 105 | AB14: 102.9 | AC14: 104.8 | AD14: 106.1
A15: Rural | B15: 2013 | C15: May | D15: 110.9 | E15: 109.8 | F15: 105.9 | G15: 107.5 | H15: 105.3 | I15: 108.1 | J15: 107.3 | K15: 106.1 | L15: 103.7 | M15: 104 | N15: 107.4 | O15: 109.9 | P15: 108.1 | Q15: 108.1 | R15: 108.8 | S15: 107.9 | T15: 108.6 | U15: NA | V15: 107.5 | W15: 106.8 | X15: 105.7 | Y15: 104.1 | Z15: 105 | AA15: 105.5 | AB15: 102.1 | AC15: 104.8 | AD15: 107.2
A16: Urban | B16: 2013 | C16: May | D16: 115.4 | E16: 114.2 | F16: 102.7 | G16: 105.5 | H16: 101.5 | I16: 110.6 | J16: 123.7 | K16: 105.2 | L16: 101.9 | M16: 105 | N16: 109.1 | O16: 111.3 | P16: 111.1 | Q16: 109.8 | R16: 108.5 | S16: 106.7 | T16: 108.3 | U16: 100.5 | V16: 107.2 | W16: 107.1 | X16: 106.2 | Y16: 103.9 | Z16: 104.6 | AA16: 105.7 | AB16: 102.6 | AC16: 104.9 | AD16: 106.6
A17: Rural+Urban | B17: 2013 | C17: May | D17: 112.3 | E17: 111.3 | F17: 104.7 | G17: 106.8 | H17: 103.9 | I17: 109.3 | J17: 112.9 | K17: 105.8 | L17: 103.1 | M17: 104.3 | N17: 108.1 | O17: 110.5 | P17: 109.2 | Q17: 108.6 | R17: 108.7 | S17: 107.4 | T17: 108.5 | U17: 100.5 | V17: 107.4 | W17: 106.9 | X17: 105.9 | Y17: 104 | Z17: 104.8 | AA17: 105.6 | AB17: 102.3 | AC17: 104.8 | AD17: 106.9
A18: Rural | B18: 2013 | C18: June | D18: 112.3 | E18: 112.1 | F18: 108.1 | G18: 108.3 | H18: 105.9 | I18: 109.2 | J18: 118 | K18: 106.8 | L18: 104.1 | M18: 105.4 | N18: 108.2 | O18: 111 | P18: 110.6 | Q18: 109 | R18: 109.7 | S18: 108.8 | T18: 109.5 | U18: NA | V18: 108.5 | W18: 107.5 | X18: 106.3 | Y18: 105 | Z18: 105.6 | AA18: 106.5 | AB18: 102.5 | AC18: 105.5 | AD18: 108.9
A19: Urban | B19: 2013 | C19: June | D19: 117 | E19: 120.1 | F19: 112.5 | G19: 107.3 | H19: 101.3 | I19: 112.4 | J19: 143.6 | K19: 105.4 | L19: 101.4 | M19: 106.4 | N19: 110 | O19: 112.2 | P19: 115 | Q19: 110.9 | R19: 109.2 | S19: 107.2 | T19: 108.9 | U19: 106.6 | V19: 108 | W19: 107.7 | X19: 106.5 | Y19: 105.2 | Z19: 105.2 | AA19: 108.1 | AB19: 103.3 | AC19: 106.1 | AD19: 109.7
A20: Rural+Urban | B20: 2013 | C20: June | D20: 113.8 | E20: 114.9 | F20: 109.8 | G20: 107.9 | H20: 104.2 | I20: 110.7 | J20: 126.7 | K20: 106.3 | L20: 103.2 | M20: 105.7 | N20: 109 | O20: 111.6 | P20: 112.2 | Q20: 109.5 | R20: 109.5 | S20: 108.1 | T20: 109.3 | U20: 106.6 | V20: 108.3 | W20: 107.6 | X20: 106.4 | Y20: 105.1 | Z20: 105.4 | AA20: 107.4 | AB20: 102.8 | AC20: 105.8 | AD20: 109.3
A21: Rural | B21: 2013 | C21: July | D21: 113.4 | E21: 114.9 | F21: 110.5 | G21: 109.3 | H21: 106.2 | I21: 110.3 | J21: 129.2 | K21: 107.1 | L21: 104.3 | M21: 106.4 | N21: 109.1 | O21: 112.1 | P21: 113.1 | Q21: 109.8 | R21: 110.5 | S21: 109.5 | T21: 110.3 | U21: NA | V21: 109.5 | W21: 108.3 | X21: 106.9 | Y21: 106.8 | Z21: 106.4 | AA21: 107.8 | AB21: 102.5 | AC21: 106.5 | AD21: 110.7
A22: Urban | B22: 2013 | C22: July | D22: 117.8 | E22: 119.2 | F22: 114 | G22: 108.3 | H22: 101.1 | I22: 113.2 | J22: 160.9 | K22: 105.1 | L22: 101.3 | M22: 107.5 | N22: 110.4 | O22: 113.1 | P22: 117.5 | Q22: 111.7 | R22: 109.8 | S22: 107.8 | T22: 109.5 | U22: 107.7 | V22: 108.6 | W22: 108.1 | X22: 107.1 | Y22: 107.3 | Z22: 105.9 | AA22: 110.1 | AB22: 103.2 | AC22: 107.3 | AD22: 111.4
A23: Rural+Urban | B23: 2013 | C23: July | D23: 114.8 | E23: 116.4 | F23: 111.9 | G23: 108.9 | H23: 104.3 | I23: 111.7 | J23: 140 | K23: 106.4 | L23: 103.3 | M23: 106.8 | N23: 109.6 | O23: 112.6 | P23: 114.7 | Q23: 110.3 | R23: 110.2 | S23: 108.8 | T23: 110 | U23: 107.7 | V23: 109.2 | W23: 108.2 | X23: 107 | Y23: 107.1 | Z23: 106.1 | AA23: 109.1 | AB23: 102.8 | AC23: 106.9 | AD23: 111
A24: Rural | B24: 2013 | C24: August | D24: 114.3 | E24: 115.4 | F24: 111.1 | G24: 110 | H24: 106.4 | I24: 110.8 | J24: 138.9 | K24: 107.4 | L24: 104.1 | M24: 106.9 | N24: 109.7 | O24: 112.6 | P24: 114.9 | Q24: 110.7 | R24: 111.3 | S24: 110.2 | T24: 111.1 | U24: NA | V24: 109.9 | W24: 108.7 | X24: 107.5 | Y24: 107.8 | Z24: 106.8 | AA24: 108.7 | AB24: 105 | AC24: 107.5 | AD24: 112.1
A25: Urban | B25: 2013 | C25: August | D25: 118.3 | E25: 120.4 | F25: 112.7 | G25: 108.9 | H25: 101.1 | I25: 108.7 | J25: 177 | K25: 104.7 | L25: 101 | M25: 108.5 | N25: 110.9 | O25: 114.3 | P25: 119.6 | Q25: 112.4 | R25: 110.6 | S25: 108.3 | T25: 110.2 | U25: 108.9 | V25: 109.3 | W25: 108.7 | X25: 107.6 | Y25: 108.1 | Z25: 106.5 | AA25: 110.8 | AB25: 106 | AC25: 108.3 | AD25: 112.7
A26: Rural+Urban | B26: 2013 | C26: August | D26: 115.6 | E26: 117.2 | F26: 111.7 | G26: 109.6 | H26: 104.5 | I26: 109.8 | J26: 151.8 | K26: 106.5 | L26: 103.1 | M26: 107.4 | N26: 110.2 | O26: 113.4 | P26: 116.6 | Q26: 111.2 | R26: 111 | S26: 109.4 | T26: 110.7 | U26: 108.9 | V26: 109.7 | W26: 108.7 | X26: 107.5 | Y26: 108 | Z26: 106.6 | AA26: 109.9 | AB26: 105.4 | AC26: 107.9 | AD26: 112.4
A27: Rural | B27: 2013 | C27: September | D27: 115.4 | E27: 115.7 | F27: 111.7 | G27: 111 | H27: 107.4 | I27: 110.9 | J27: 154 | K27: 108.1 | L27: 104.2 | M27: 107.9 | N27: 110.4 | O27: 114 | P27: 117.8 | Q27: 111.7 | R27: 112.7 | S27: 111.4 | T27: 112.5 | U27: NA | V27: 111.1 | W27: 109.6 | X27: 108.3 | Y27: 109.3 | Z27: 107.7 | AA27: 109.8 | AB27: 106.7 | AC27: 108.7 | AD27: 114.2
A28: Urban | B28: 2013 | C28: September | D28: 118.6 | E28: 119.1 | F28: 113.2 | G28: 109.6 | H28: 101.7 | I28: 103.2 | J28: 174.3 | K28: 105.1 | L28: 100.8 | M28: 109.1 | N28: 111.1 | O28: 115.4 | P28: 119.2 | Q28: 112.9 | R28: 111.4 | S28: 109 | T28: 111.1 | U28: 109.7 | V28: 109.5 | W28: 109.6 | X28: 107.9 | Y28: 110.4 | Z28: 107.4 | AA28: 111.2 | AB28: 106.9 | AC28: 109.4 | AD28: 113.2
A29: Rural+Urban | B29: 2013 | C29: September | D29: 116.4 | E29: 116.9 | F29: 112.3 | G29: 110.5 | H29: 105.3 | I29: 107.3 | J29: 160.9 | K29: 107.1 | L29: 103.1 | M29: 108.3 | N29: 110.7 | O29: 114.6 | P29: 118.3 | Q29: 112 | R29: 112.2 | S29: 110.4 | T29: 111.9 | U29: 109.7 | V29: 110.5 | W29: 109.6 | X29: 108.1 | Y29: 109.9 | Z29: 107.5 | AA29: 110.6 | AB29: 106.8 | AC29: 109 | AD29: 113.7
A30: Rural | B30: 2013 | C30: October | D30: 116.3 | E30: 115.4 | F30: 112.6 | G30: 111.7 | H30: 107.7 | I30: 113.2 | J30: 164.9 | K30: 108.3 | L30: 103.9 | M30: 108.2 | N30: 111.1 | O30: 114.9 | P30: 119.8 | Q30: 112.2 | R30: 113.6 | S30: 112.3 | T30: 113.4 | U30: NA | V30: 111.6 | W30: 110.4 | X30: 108.9 | Y30: 109.3 | Z30: 108.3 | AA30: 110.2 | AB30: 107.5 | AC30: 109.1 | AD30: 115.5
A31: Urban | B31: 2013 | C31: October | D31: 118.9 | E31: 118.1 | F31: 114.5 | G31: 110.4 | H31: 102.3 | I31: 106.2 | J31: 183.5 | K31: 105.3 | L31: 100.2 | M31: 109.6 | N31: 111.4 | O31: 116 | P31: 120.8 | Q31: 113.5 | R31: 112.5 | S31: 109.7 | T31: 112 | U31: 110.5 | V31: 109.7 | W31: 110.2 | X31: 108.2 | Y31: 109.7 | Z31: 108 | AA31: 111.3 | AB31: 107.3 | AC31: 109.4 | AD31: 114
A32: Rural+Urban | B32: 2013 | C32: October | D32: 117.1 | E32: 116.3 | F32: 113.3 | G32: 111.2 | H32: 105.7 | I32: 109.9 | J32: 171.2 | K32: 107.3 | L32: 102.7 | M32: 108.7 | N32: 111.2 | O32: 115.4 | P32: 120.2 | Q32: 112.5 | R32: 113.2 | S32: 111.2 | T32: 112.8 | U32: 110.5 | V32: 110.9 | W32: 110.3 | X32: 108.6 | Y32: 109.5 | Z32: 108.1 | AA32: 110.8 | AB32: 107.4 | AC32: 109.2 | AD32: 114.8
A33: Rural | B33: 2013 | C33: November | D33: 117.3 | E33: 114.9 | F33: 116.2 | G33: 112.8 | H33: 108.9 | I33: 116.6 | J33: 178.1 | K33: 109.1 | L33: 103.6 | M33: 109 | N33: 111.8 | O33: 116 | P33: 122.5 | Q33: 112.8 | R33: 114.6 | S33: 113.1 | T33: 114.4 | U33: NA | V33: 112.6 | W33: 111.3 | X33: 109.7 | Y33: 109.6 | Z33: 108.7 | AA33: 111 | AB33: 108.2 | AC33: 109.8 | AD33: 117.4
A34: Urban | B34: 2013 | C34: November | D34: 119.8 | E34: 116.3 | F34: 122.6 | G34: 112 | H34: 103.2 | I34: 110 | J34: 192.8 | K34: 106.3 | L34: 99.5 | M34: 110.3 | N34: 111.8 | O34: 117.1 | P34: 122.9 | Q34: 114.1 | R34: 113.5 | S34: 110.3 | T34: 113 | U34: 111.1 | V34: 110 | W34: 110.9 | X34: 108.6 | Y34: 109.5 | Z34: 108.5 | AA34: 111.3 | AB34: 107.9 | AC34: 109.6 | AD34: 115
A35: Rural+Urban | B35: 2013 | C35: November | D35: 118.1 | E35: 115.4 | F35: 118.7 | G35: 112.5 | H35: 106.8 | I35: 113.5 | J35: 183.1 | K35: 108.2 | L35: 102.2 | M35: 109.4 | N35: 111.8 | O35: 116.5 | P35: 122.6 | Q35: 113.1 | R35: 114.2 | S35: 111.9 | T35: 113.8 | U35: 111.1 | V35: 111.6 | W35: 111.1 | X35: 109.3 | Y35: 109.5 | Z35: 108.6 | AA35: 111.2 | AB35: 108.1 | AC35: 109.7 | AD35: 116.3
A36: Rural | B36: 2013 | C36: December | D36: 118.4 | E36: 115.9 | F36: 120.4 | G36: 113.8 | H36: 109.5 | I36: 115.5 | J36: 145.7 | K36: 109.5 | L36: 102.9 | M36: 109.8 | N36: 112.1 | O36: 116.8 | P36: 118.7 | Q36: 113.6 | R36: 115.8 | S36: 114 | T36: 115.5 | U36: NA | V36: 112.8 | W36: 112.1 | X36: 110.1 | Y36: 109.9 | Z36: 109.2 | AA36: 111.6 | AB36: 108.1 | AC36: 110.1 | AD36: 115.5
A37: Urban | B37: 2013 | C37: December | D37: 120.5 | E37: 118.1 | F37: 128.5 | G37: 112.8 | H37: 103.4 | I37: 110.7 | J37: 144.8 | K37: 107.1 | L37: 98.6 | M37: 111.9 | N37: 112.1 | O37: 118.1 | P37: 117.8 | Q37: 115 | R37: 114.2 | S37: 110.9 | T37: 113.7 | U37: 110.7 | V37: 110.4 | W37: 111.3 | X37: 109 | Y37: 109.7 | Z37: 108.9 | AA37: 111.4 | AB37: 107.7 | AC37: 109.8 | AD37: 113.3
A38: Rural+Urban | B38: 2013 | C38: December | D38: 119.1 | E38: 116.7 | F38: 123.5 | G38: 113.4 | H38: 107.3 | I38: 113.3 | J38: 145.4 | K38: 108.7 | L38: 101.5 | M38: 110.5 | N38: 112.1 | O38: 117.4 | P38: 118.4 | Q38: 114 | R38: 115.2 | S38: 112.7 | T38: 114.8 | U38: 110.7 | V38: 111.9 | W38: 111.7 | X38: 109.7 | Y38: 109.8 | Z38: 109 | AA38: 111.5 | AB38: 107.9 | AC38: 110 | AD38: 114.5
A39: Rural | B39: 2014 | C39: January | D39: 118.9 | E39: 117.1 | F39: 120.5 | G39: 114.4 | H39: 109 | I39: 115.5 | J39: 123.9 | K39: 109.6 | L39: 101.8 | M39: 110.2 | N39: 112.4 | O39: 117.3 | P39: 116 | Q39: 114 | R39: 116.5 | S39: 114.5 | T39: 116.2 | U39: NA | V39: 113 | W39: 112.6 | X39: 110.6 | Y39: 110.5 | Z39: 109.6 | AA39: 111.8 | AB39: 108.3 | AC39: 110.6 | AD39: 114.2
A40: Urban | B40: 2014 | C40: January | D40: 121.2 | E40: 122 | F40: 129.9 | G40: 113.6 | H40: 102.9 | I40: 112.1 | J40: 118.9 | K40: 107.5 | L40: 96.9 | M40: 112.7 | N40: 112.1 | O40: 119 | P40: 115.5 | Q40: 115.7 | R40: 114.8 | S40: 111.3 | T40: 114.3 | U40: 111.6 | V40: 111 | W40: 111.9 | X40: 109.7 | Y40: 110.8 | Z40: 109.8 | AA40: 111.5 | AB40: 108 | AC40: 110.5 | AD40: 112.9
...

Sheet Q1 CPI Basket Contri Analysis
B2: 2023
B3: May
A4: Item Category | B4: Broader Category | C4: Rural | D4: Urban | E4: Rural+Urban | H4: Sector | I4: Broader Category | J4: Rural | K4: Urban | L4: Rural+Urban | M4: =$H$5 -> Rural+Urban
A5: Cereals and products | B5: =VLOOKUP($A5,'[1]EDA and Analysis1'!$A:$B,2,0) -> Basic Food Items | C5: {=INDEX('Cleaned Data'!$D$3:$AD$374, MATCH(1, ('Cleaned Data'!$A$3:$A$374 = 'Q1 CPI Basket Contri Analysis'!$C$4)* ('Cleaned Data'!$B$3:$B$374 ='Q1 CPI Basket Contri Analysis'!$B$2)* ('Cleaned Data'!$C$3:$C$374 = 'Q1 CPI Basket Contri Analysis'!$B$3), 0),MATCH($A5,'Cleaned Data'!$D$1:$AD$1,0))} -> 173.2 | D5: {=INDEX('Cleaned Data'!$D$3:$AD$374, MATCH(1, ('Cleaned Data'!$A$3:$A$374 = $D$4)* ('Cleaned Data'!$B$3:$B$374 ='Q1 CPI Basket Contri Analysis'!$B$2)* ('Cleaned Data'!$C$3:$C$374 = 'Q1 CPI Basket Contri Analysis'!$B$3), 0),MATCH($A5,'Cleaned Data'!$D$1:$AD$1,0))} -> 174.7 | E5: {=INDEX('Cleaned Data'!$D$3:$AD$374, MATCH(1, ('Cleaned Data'!$A$3:$A$374 = $E$4)* ('Cleaned Data'!$B$3:$B$374 ='Q1 CPI Basket Contri Analysis'!$B$2)* ('Cleaned Data'!$C$3:$C$374 = 'Q1 CPI Basket Contri Analysis'!$B$3), 0),MATCH($A5,'Cleaned Data'!$D$1:$AD$1,0))} -> 173.7 | H5: Rural+Urban | I5: Basic Food Items | J5: =SUMIF($B$5:$B$30,$I5,$C$5:$C$30) -> 1622.2 | K5: =SUMIF($B$5:$B$30,$I5,D$5:D$30) -> 1664.2 | L5: =SUMIF($B$5:$B$30,$I5,E$5:E$30) -> 1637.5 | M5: =INDEX($J$5:$L$9, MATCH($I5,$I$5:$I$9,0), MATCH($H$5,$J$4:$L$4,0)) -> 1637.5
A6: Meat and fish | B6: =VLOOKUP($A6,'[1]EDA and Analysis1'!$A:$B,2,0) -> Basic Food Items | C6: {=INDEX('Cleaned Data'!$D$3:$AD$374, MATCH(1, ('Cleaned Data'!$A$3:$A$374 = 'Q1 CPI Basket Contri Analysis'!$C$4)* ('Cleaned Data'!$B$3:$B$374 ='Q1 CPI Basket Contri Analysis'!$B$2)* ('Cleaned Data'!$C$3:$C$374 = 'Q1 CPI Basket Contri Analysis'!$B$3), 0),MATCH($A6,'Cleaned Data'!$D$1:$AD$1,0))} -> 211.5 | D6: {=INDEX('Cleaned Data'!$D$3:$AD$374, MATCH(1, ('Cleaned Data'!$A$3:$A$374 = $D$4)* ('Cleaned Data'!$B$3:$B$374 ='Q1 CPI Basket Contri Analysis'!$B$2)* ('Cleaned Data'!$C$3:$C$374 = 'Q1 CPI Basket Contri Analysis'!$B$3), 0),MATCH($A6,'Cleaned Data'!$D$1:$AD$1,0))} -> 219.4 | E6: {=INDEX('Cleaned Data'!$D$3:$AD$374, MATCH(1, ('Cleaned Data'!$A$3:$A$374 = $E$4)* ('Cleaned Data'!$B$3:$B$374 ='Q1 CPI Basket Contri Analysis'!$B$2)* ('Cleaned Data'!$C$3:$C$374 = 'Q1 CPI Basket Contri Analysis'!$B$3), 0),MATCH($A6,'Cleaned Data'!$D$1:$AD$1,0))} -> 214.3 | I6: Other Food and Intoxicants | J6: =SUMIF($B$5:$B$30,$I6,$C$5:$C$30) -> 868.4 | K6: =SUMIF($B$5:$B$30,$I6,D$5:D$30) -> 875.1 | L6: =SUMIF($B$5:$B$30,$I6,E$5:E$30) -> 870.4 | M6: =INDEX($J$5:$L$9, MATCH($I6,$I$5:$I$9,0), MATCH($H$5,$J$4:$L$4,0)) -> 870.4
A7: Egg | B7: =VLOOKUP($A7,'[1]EDA and Analysis1'!$A:$B,2,0) -> Basic Food Items | C7: {=INDEX('Cleaned Data'!$D$3:$AD$374, MATCH(1, ('Cleaned Data'!$A$3:$A$374 = 'Q1 CPI Basket Contri Analysis'!$C$4)* ('Cleaned Data'!$B$3:$B$374 ='Q1 CPI Basket Contri Analysis'!$B$2)* ('Cleaned Data'!$C$3:$C$374 = 'Q1 CPI Basket Contri Analysis'!$B$3), 0),MATCH($A7,'Cleaned Data'!$D$1:$AD$1,0))} -> 171 | D7: {=INDEX('Cleaned Data'!$D$3:$AD$374, MATCH(1, ('Cleaned Data'!$A$3:$A$374 = $D$4)* ('Cleaned Data'!$B$3:$B$374 ='Q1 CPI Basket Contri Analysis'!$B$2)* ('Cleaned Data'!$C$3:$C$374 = 'Q1 CPI Basket Contri Analysis'!$B$3), 0),MATCH($A7,'Cleaned Data'!$D$1:$AD$1,0))} -> 176.7 | E7: {=INDEX('Cleaned Data'!$D$3:$AD$374, MATCH(1, ('Cleaned Data'!$A$3:$A$374 = $E$4)* ('Cleaned Data'!$B$3:$B$374 ='Q1 CPI Basket Contri Analysis'!$B$2)* ('Cleaned Data'!$C$3:$C$374 = 'Q1 CPI Basket Contri Analysis'!$B$3), 0),MATCH($A7,'Cleaned Data'!$D$1:$AD$1,0))} -> 173.2 | I7: Clothing and footwear | J7: =SUMIF($B$5:$B$30,$I7,$C$5:$C$30) -> 569.9 | K7: =SUMIF($B$5:$B$30,$I7,D$5:D$30) -> 528.7 | L7: =SUMIF($B$5:$B$30,$I7,E$5:E$30) -> 553.2 | M7: =INDEX($J$5:$L$9, MATCH($I7,$I$5:$I$9,0), MATCH($H$5,$J$4:$L$4,0)) -> 553.2
A8: Milk and products | B8: =VLOOKUP($A8,'[1]EDA and Analysis1'!$A:$B,2,0) -> Basic Food Items | C8: {=INDEX('Cleaned Data'!$D$3:$AD$374, MATCH(1, ('Cleaned Data'!$A$3:$A$374 = 'Q1 CPI Basket Contri Analysis'!$C$4)* ('Cleaned Data'!$B$3:$B$374 ='Q1 CPI Basket Contri Analysis'!$B$2)* ('Cleaned Data'!$C$3:$C$374 = 'Q1 CPI Basket Contri Analysis'!$B$3), 0),MATCH($A8,'Cleaned Data'!$D$1:$AD$1,0))} -> 179.6 | D8: {=INDEX('Cleaned Data'!$D$3:$AD$374, MATCH(1, ('Cleaned Data'!$A$3:$A$374 = $D$4)* ('Cleaned Data'!$B$3:$B$374 ='Q1 CPI Basket Contri Analysis'!$B$2)* ('Cleaned Data'!$C$3:$C$374 = 'Q1 CPI Basket Contri Analysis'!$B$3), 0),MATCH($A8,'Cleaned Data'!$D$1:$AD$1,0))} -> 179.4 | E8: {=INDEX('Cleaned Data'!$D$3:$AD$374, MATCH(1, ('Cleaned Data'!$A$3:$A$374 = $E$4)* ('Cleaned Data'!$B$3:$B$374 ='Q1 CPI Basket Contri Analysis'!$B$2)* ('Cleaned Data'!$C$3:$C$374 = 'Q1 CPI Basket Contri Analysis'!$B$3), 0),MATCH($A8,'Cleaned Data'!$D$1:$AD$1,0))} -> 179.5 | I8: Housing and Utilities | J8: =SUMIF($B$5:$B$30,$I8,$C$5:$C$30) -> 362.3 | K8: =SUMIF($B$5:$B$30,$I8,D$5:D$30) -> 529.1 | L8: =SUMIF($B$5:$B$30,$I8,E$5:E$30) -> 533.6 | M8: =INDEX($J$5:$L$9, MATCH($I8,$I$5:$I$9,0), MATCH($H$5,$J$4:$L$4,0)) -> 533.6
A9: Oils and fats | B9: =VLOOKUP($A9,'[1]EDA and Analysis1'!$A:$B,2,0) -> Basic Food Items | C9: {=INDEX('Cleaned Data'!$D$3:$AD$374, MATCH(1, ('Cleaned Data'!$A$3:$A$374 = 'Q1 CPI Basket Contri Analysis'!$C$4)* ('Cleaned Data'!$B$3:$B$374 ='Q1 CPI Basket Contri Analysis'!$B$2)* ('Cleaned Data'!$C$3:$C$374 = 'Q1 CPI Basket Contri Analysis'!$B$3), 0),MATCH($A9,'Cleaned Data'!$D$1:$AD$1,0))} -> 173.3 | D9: {=INDEX('Cleaned Data'!$D$3:$AD$374, MATCH(1, ('Cleaned Data'!$A$3:$A$374 = $D$4)* ('Cleaned Data'!$B$3:$B$374 ='Q1 CPI Basket Contri Analysis'!$B$2)* ('Cleaned Data'!$C$3:$C$374 = 'Q1 CPI Basket Contri Analysis'!$B$3), 0),MATCH($A9,'Cleaned Data'!$D$1:$AD$1,0))} -> 164.4 | E9: {=INDEX('Cleaned Data'!$D$3:$AD$374, MATCH(1, ('Cleaned Data'!$A$3:$A$374 = $E$4)* ('Cleaned Data'!$B$3:$B$374 ='Q1 CPI Basket Contri Analysis'!$B$2)* ('Cleaned Data'!$C$3:$C$374 = 'Q1 CPI Basket Contri Analysis'!$B$3), 0),MATCH($A9,'Cleaned Data'!$D$1:$AD$1,0))} -> 170 | I9: Services and Miscellaneous | J9: =SUMIF($B$5:$B$30,$I9,$C$5:$C$30) -> 1076 | K9: =SUMIF($B$5:$B$30,$I9,D$5:D$30) -> 1043.8 | L9: =SUMIF($B$5:$B$30,$I9,E$5:E$30) -> 1059.7 | M9: =INDEX($J$5:$L$9, MATCH($I9,$I$5:$I$9,0), MATCH($H$5,$J$4:$L$4,0)) -> 1059.7
A10: Fruits | B10: =VLOOKUP($A10,'[1]EDA and Analysis1'!$A:$B,2,0) -> Basic Food Items | C10: {=INDEX('Cleaned Data'!$D$3:$AD$374, MATCH(1, ('Cleaned Data'!$A$3:$A$374 = 'Q1 CPI Basket Contri Analysis'!$C$4)* ('Cleaned Data'!$B$3:$B$374 ='Q1 CPI Basket Contri Analysis'!$B$2)* ('Cleaned Data'!$C$3:$C$374 = 'Q1 CPI Basket Contri Analysis'!$B$3), 0),MATCH($A10,'Cleaned Data'!$D$1:$AD$1,0))} -> 169 | D10: {=INDEX('Cleaned Data'!$D$3:$AD$374, MATCH(1, ('Cleaned Data'!$A$3:$A$374 = $D$4)* ('Cleaned Data'!$B$3:$B$374 ='Q1 CPI Basket Contri Analysis'!$B$2)* ('Cleaned Data'!$C$3:$C$374 = 'Q1 CPI Basket Contri Analysis'!$B$3), 0),MATCH($A10,'Cleaned Data'!$D$1:$AD$1,0))} -> 175.8 | E10: {=INDEX('Cleaned Data'!$D$3:$AD$374, MATCH(1, ('Cleaned Data'!$A$3:$A$374 = $E$4)* ('Cleaned Data'!$B$3:$B$374 ='Q1 CPI Basket Contri Analysis'!$B$2)* ('Cleaned Data'!$C$3:$C$374 = 'Q1 CPI Basket Contri Analysis'!$B$3), 0),MATCH($A10,'Cleaned Data'!$D$1:$AD$1,0))} -> 172.2
A11: Vegetables | B11: =VLOOKUP($A11,'[1]EDA and Analysis1'!$A:$B,2,0) -> Basic Food Items | C11: {=INDEX('Cleaned Data'!$D$3:$AD$374, MATCH(1, ('Cleaned Data'!$A$3:$A$374 = 'Q1 CPI Basket Contri Analysis'!$C$4)* ('Cleaned Data'!$B$3:$B$374 ='Q1 CPI Basket Contri Analysis'!$B$2)* ('Cleaned Data'!$C$3:$C$374 = 'Q1 CPI Basket Contri Analysis'!$B$3), 0),MATCH($A11,'Cleaned Data'!$D$1:$AD$1,0))} -> 148.7 | D11: {=INDEX('Cleaned Data'!$D$3:$AD$374, MATCH(1, ('Cleaned Data'!$A$3:$A$374 = $D$4)* ('Cleaned Data'!$B$3:$B$374 ='Q1 CPI Basket Contri Analysis'!$B$2)* ('Cleaned Data'!$C$3:$C$374 = 'Q1 CPI Basket Contri Analysis'!$B$3), 0),MATCH($A11,'Cleaned Data'!$D$1:$AD$1,0))} -> 185 | E11: {=INDEX('Cleaned Data'!$D$3:$AD$374, MATCH(1, ('Cleaned Data'!$A$3:$A$374 = $E$4)* ('Cleaned Data'!$B$3:$B$374 ='Q1 CPI Basket Contri Analysis'!$B$2)* ('Cleaned Data'!$C$3:$C$374 = 'Q1 CPI Basket Contri Analysis'!$B$3), 0),MATCH($A11,'Cleaned Data'!$D$1:$AD$1,0))} -> 161
A12: Pulses and products | B12: =VLOOKUP($A12,'[1]EDA and Analysis1'!$A:$B,2,0) -> Basic Food Items | C12: {=INDEX('Cleaned Data'!$D$3:$AD$374, MATCH(1, ('Cleaned Data'!$A$3:$A$374 = 'Q1 CPI Basket Contri Analysis'!$C$4)* ('Cleaned Data'!$B$3:$B$374 ='Q1 CPI Basket Contri Analysis'!$B$2)* ('Cleaned Data'!$C$3:$C$374 = 'Q1 CPI Basket Contri Analysis'!$B$3), 0),MATCH($A12,'Cleaned Data'!$D$1:$AD$1,0))} -> 174.9 | D12: {=INDEX('Cleaned Data'!$D$3:$AD$374, MATCH(1, ('Cleaned Data'!$A$3:$A$374 = $D$4)* ('Cleaned Data'!$B$3:$B$374 ='Q1 CPI Basket Contri Analysis'!$B$2)* ('Cleaned Data'!$C$3:$C$374 = 'Q1 CPI Basket Contri Analysis'!$B$3), 0),MATCH($A12,'Cleaned Data'!$D$1:$AD$1,0))} -> 176.9 | E12: {=INDEX('Cleaned Data'!$D$3:$AD$374, MATCH(1, ('Cleaned Data'!$A$3:$A$374 = $E$4)* ('Cleaned Data'!$B$3:$B$374 ='Q1 CPI Basket Contri Analysis'!$B$2)* ('Cleaned Data'!$C$3:$C$374 = 'Q1 CPI Basket Contri Analysis'!$B$3), 0),MATCH($A12,'Cleaned Data'!$D$1:$AD$1,0))} -> 175.6
A13: Sugar and Confectionery | B13: =VLOOKUP($A13,'[1]EDA and Analysis1'!$A:$B,2,0) -> Other Food and Intoxicants | C13: {=INDEX('Cleaned Data'!$D$3:$AD$374, MATCH(1, ('Cleaned Data'!$A$3:$A$374 = 'Q1 CPI Basket Contri Analysis'!$C$4)* ('Cleaned Data'!$B$3:$B$374 ='Q1 CPI Basket Contri Analysis'!$B$2)* ('Cleaned Data'!$C$3:$C$374 = 'Q1 CPI Basket Contri Analysis'!$B$3), 0),MATCH($A13,'Cleaned Data'!$D$1:$AD$1,0))} -> 121.9 | D13: {=INDEX('Cleaned Data'!$D$3:$AD$374, MATCH(1, ('Cleaned Data'!$A$3:$A$374 = $D$4)* ('Cleaned Data'!$B$3:$B$374 ='Q1 CPI Basket Contri Analysis'!$B$2)* ('Cleaned Data'!$C$3:$C$374 = 'Q1 CPI Basket Contri Analysis'!$B$3), 0),MATCH($A13,'Cleaned Data'!$D$1:$AD$1,0))} -> 124.2 | E13: {=INDEX('Cleaned Data'!$D$3:$AD$374, MATCH(1, ('Cleaned Data'!$A$3:$A$374 = $E$4)* ('Cleaned Data'!$B$3:$B$374 ='Q1 CPI Basket Contri Analysis'!$B$2)* ('Cleaned Data'!$C$3:$C$374 = 'Q1 CPI Basket Contri Analysis'!$B$3), 0),MATCH($A13,'Cleaned Data'!$D$1:$AD$1,0))} -> 122.7
A14: Spices | B14: =VLOOKUP($A14,'[1]EDA and Analysis1'!$A:$B,2,0) -> Basic Food Items | C14: {=INDEX('Cleaned Data'!$D$3:$AD$374, MATCH(1, ('Cleaned Data'!$A$3:$A$374 = 'Q1 CPI Basket Contri Analysis'!$C$4)* ('Cleaned Data'!$B$3:$B$374 ='Q1 CPI Basket Contri Analysis'!$B$2)* ('Cleaned Data'!$C$3:$C$374 = 'Q1 CPI Basket Contri Analysis'!$B$3), 0),MATCH($A14,'Cleaned Data'!$D$1:$AD$1,0))} -> 221 | D14: {=INDEX('Cleaned Data'!$D$3:$AD$374, MATCH(1, ('Cleaned Data'!$A$3:$A$374 = $D$4)* ('Cleaned Data'!$B$3:$B$374 ='Q1 CPI Basket Contri Analysis'!$B$2)* ('Cleaned Data'!$C$3:$C$374 = 'Q1 CPI Basket Contri Analysis'!$B$3), 0),MATCH($A14,'Cleaned Data'!$D$1:$AD$1,0))} -> 211.9 | E14: {=INDEX('Cleaned Data'!$D$3:$AD$374, MATCH(1, ('Cleaned Data'!$A$3:$A$374 = $E$4)* ('Cleaned Data'!$B$3:$B$374 ='Q1 CPI Basket Contri Analysis'!$B$2)* ('Cleaned Data'!$C$3:$C$374 = 'Q1 CPI Basket Contri Analysis'!$B$3), 0),MATCH($A14,'Cleaned Data'!$D$1:$AD$1,0))} -> 218
A15: Non-alcoholic beverages | B15: =VLOOKUP($A15,'[1]EDA and Analysis1'!$A:$B,2,0) -> Other Food and Intoxicants | C15: {=INDEX('Cleaned Data'!$D$3:$AD$374, MATCH(1, ('Cleaned Data'!$A$3:$A$374 = 'Q1 CPI Basket Contri Analysis'!$C$4)* ('Cleaned Data'!$B$3:$B$374 ='Q1 CPI Basket Contri Analysis'!$B$2)* ('Cleaned Data'!$C$3:$C$374 = 'Q1 CPI Basket Contri Analysis'!$B$3), 0),MATCH($A15,'Cleaned Data'!$D$1:$AD$1,0))} -> 178.7 | D15: {=INDEX('Cleaned Data'!$D$3:$AD$374, MATCH(1, ('Cleaned Data'!$A$3:$A$374 = $D$4)* ('Cleaned Data'!$B$3:$B$374 ='Q1 CPI Basket Contri Analysis'!$B$2)* ('Cleaned Data'!$C$3:$C$374 = 'Q1 CPI Basket Contri Analysis'!$B$3), 0),MATCH($A15,'Cleaned Data'!$D$1:$AD$1,0))} -> 165.9 | E15: {=INDEX('Cleaned Data'!$D$3:$AD$374, MATCH(1, ('Cleaned Data'!$A$3:$A$374 = $E$4)* ('Cleaned Data'!$B$3:$B$374 ='Q1 CPI Basket Contri Analysis'!$B$2)* ('Cleaned Data'!$C$3:$C$374 = 'Q1 CPI Basket Contri Analysis'!$B$3), 0),MATCH($A15,'Cleaned Data'!$D$1:$AD$1,0))} -> 173.4
A16: Prepared meals, snacks, sweets, etc. | B16: =VLOOKUP($A16,'[1]EDA and Analysis1'!$A:$B,2,0) -> Other Food and Intoxicants | C16: {=INDEX('Cleaned Data'!$D$3:$AD$374, MATCH(1, ('Cleaned Data'!$A$3:$A$374 = 'Q1 CPI Basket Contri Analysis'!$C$4)* ('Cleaned Data'!$B$3:$B$374 ='Q1 CPI Basket Contri Analysis'!$B$2)* ('Cleaned Data'!$C$3:$C$374 = 'Q1 CPI Basket Contri Analysis'!$B$3), 0),MATCH($A16,'Cleaned Data'!$D$1:$AD$1,0))} -> 191.1 | D16: {=INDEX('Cleaned Data'!$D$3:$AD$374, MATCH(1, ('Cleaned Data'!$A$3:$A$374 = $D$4)* ('Cleaned Data'!$B$3:$B$374 ='Q1 CPI Basket Contri Analysis'!$B$2)* ('Cleaned Data'!$C$3:$C$374 = 'Q1 CPI Basket Contri Analysis'!$B$3), 0),MATCH($A16,'Cleaned Data'!$D$1:$AD$1,0))} -> 197.7 | E16: {=INDEX('Cleaned Data'!$D$3:$AD$374, MATCH(1, ('Cleaned Data'!$A$3:$A$374 = $E$4)* ('Cleaned Data'!$B$3:$B$374 ='Q1 CPI Basket Contri Analysis'!$B$2)* ('Cleaned Data'!$C$3:$C$374 = 'Q1 CPI Basket Contri Analysis'!$B$3), 0),MATCH($A16,'Cleaned Data'!$D$1:$AD$1,0))} -> 194.2
A17: Food and beverages | B17: =VLOOKUP($A17,'[1]EDA and Analysis1'!$A:$B,2,0) -> Other Food and Intoxicants | C17: {=INDEX('Cleaned Data'!$D$3:$AD$374, MATCH(1, ('Cleaned Data'!$A$3:$A$374 = 'Q1 CPI Basket Contri Analysis'!$C$4)* ('Cleaned Data'!$B$3:$B$374 ='Q1 CPI Basket Contri Analysis'!$B$2)* ('Cleaned Data'!$C$3:$C$374 = 'Q1 CPI Basket Contri Analysis'!$B$3), 0),MATCH($A17,'Cleaned Data'!$D$1:$AD$1,0))} -> 176.8 | D17: {=INDEX('Cleaned Data'!$D$3:$AD$374, MATCH(1, ('Cleaned Data'!$A$3:$A$374 = $D$4)* ('Cleaned Data'!$B$3:$B$374 ='Q1 CPI Basket Contri Analysis'!$B$2)* ('Cleaned Data'!$C$3:$C$374 = 'Q1 CPI Basket Contri Analysis'!$B$3), 0),MATCH($A17,'Cleaned Data'!$D$1:$AD$1,0))} -> 183.1 | E17: {=INDEX('Cleaned Data'!$D$3:$AD$374, MATCH(1, ('Cleaned Data'!$A$3:$A$374 = $E$4)* ('Cleaned Data'!$B$3:$B$374 ='Q1 CPI Basket Contri Analysis'!$B$2)* ('Cleaned Data'!$C$3:$C$374 = 'Q1 CPI Basket Contri Analysis'!$B$3), 0),MATCH($A17,'Cleaned Data'!$D$1:$AD$1,0))} -> 179.1
A18: Pan, tobacco, and intoxicants | B18: =VLOOKUP($A18,'[1]EDA and Analysis1'!$A:$B,2,0) -> Other Food and Intoxicants | C18: {=INDEX('Cleaned Data'!$D$3:$AD$374, MATCH(1, ('Cleaned Data'!$A$3:$A$374 = 'Q1 CPI Basket Contri Analysis'!$C$4)* ('Cleaned Data'!$B$3:$B$374 ='Q1 CPI Basket Contri Analysis'!$B$2)* ('Cleaned Data'!$C$3:$C$374 = 'Q1 CPI Basket Contri Analysis'!$B$3), 0),MATCH($A18,'Cleaned Data'!$D$1:$AD$1,0))} -> 199.9 | D18: {=INDEX('Cleaned Data'!$D$3:$AD$374, MATCH(1, ('Cleaned Data'!$A$3:$A$374 = $D$4)* ('Cleaned Data'!$B$3:$B$374 ='Q1 CPI Basket Contri Analysis'!$B$2)* ('Cleaned Data'!$C$3:$C$374 = 'Q1 CPI Basket Contri Analysis'!$B$3), 0),MATCH($A18,'Cleaned Data'!$D$1:$AD$1,0))} -> 204.2 | E18: {=INDEX('Cleaned Data'!$D$3:$AD$374, MATCH(1, ('Cleaned Data'!$A$3:$A$374 = $E$4)* ('Cleaned Data'!$B$3:$B$374 ='Q1 CPI Basket Contri Analysis'!$B$2)* ('Cleaned Data'!$C$3:$C$374 = 'Q1 CPI Basket Contri Analysis'!$B$3), 0),MATCH($A18,'Cleaned Data'!$D$1:$AD$1,0))} -> 201
A19: Clothing | B19: =VLOOKUP($A19,'[1]EDA and Analysis1'!$A:$B,2,0) -> Clothing and footwear | C19: {=INDEX('Cleaned Data'!$D$3:$AD$374, MATCH(1, ('Cleaned Data'!$A$3:$A$374 = 'Q1 CPI Basket Contri Analysis'!$C$4)* ('Cleaned Data'!$B$3:$B$374 ='Q1 CPI Basket Contri Analysis'!$B$2)* ('Cleaned Data'!$C$3:$C$374 = 'Q1 CPI Basket Contri Analysis'!$B$3), 0),MATCH($A19,'Cleaned Data'!$D$1:$AD$1,0))} -> 191.2 | D19: {=INDEX('Cleaned Data'!$D$3:$AD$374, MATCH(1, ('Cleaned Data'!$A$3:$A$374 = $D$4)* ('Cleaned Data'!$B$3:$B$374 ='Q1 CPI Basket Contri Analysis'!$B$2)* ('Cleaned Data'!$C$3:$C$374 = 'Q1 CPI Basket Contri Analysis'!$B$3), 0),MATCH($A19,'Cleaned Data'!$D$1:$AD$1,0))} -> 181.3 | E19: {=INDEX('Cleaned Data'!$D$3:$AD$374, MATCH(1, ('Cleaned Data'!$A$3:$A$374 = $E$4)* ('Cleaned Data'!$B$3:$B$374 ='Q1 CPI Basket Contri Analysis'!$B$2)* ('Cleaned Data'!$C$3:$C$374 = 'Q1 CPI Basket Contri Analysis'!$B$3), 0),MATCH($A19,'Cleaned Data'!$D$1:$AD$1,0))} -> 187.3
A20: Footwear | B20: =VLOOKUP($A20,'[1]EDA and Analysis1'!$A:$B,2,0) -> Clothing and footwear | C20: {=INDEX('Cleaned Data'!$D$3:$AD$374, MATCH(1, ('Cleaned Data'!$A$3:$A$374 = 'Q1 CPI Basket Contri Analysis'!$C$4)* ('Cleaned Data'!$B$3:$B$374 ='Q1 CPI Basket Contri Analysis'!$B$2)* ('Cleaned Data'!$C$3:$C$374 = 'Q1 CPI Basket Contri Analysis'!$B$3), 0),MATCH($A20,'Cleaned Data'!$D$1:$AD$1,0))} -> 187.9 | D20: {=INDEX('Cleaned Data'!$D$3:$AD$374, MATCH(1, ('Cleaned Data'!$A$3:$A$374 = $D$4)* ('Cleaned Data'!$B$3:$B$374 ='Q1 CPI Basket Contri Analysis'!$B$2)* ('Cleaned Data'!$C$3:$C$374 = 'Q1 CPI Basket Contri Analysis'!$B$3), 0),MATCH($A20,'Cleaned Data'!$D$1:$AD$1,0))} -> 168.1 | E20: {=INDEX('Cleaned Data'!$D$3:$AD$374, MATCH(1, ('Cleaned Data'!$A$3:$A$374 = $E$4)* ('Cleaned Data'!$B$3:$B$374 ='Q1 CPI Basket Contri Analysis'!$B$2)* ('Cleaned Data'!$C$3:$C$374 = 'Q1 CPI Basket Contri Analysis'!$B$3), 0),MATCH($A20,'Cleaned Data'!$D$1:$AD$1,0))} -> 179.7
A21: Clothing and footwear | B21: =VLOOKUP($A21,'[1]EDA and Analysis1'!$A:$B,2,0) -> Clothing and footwear | C21: {=INDEX('Cleaned Data'!$D$3:$AD$374, MATCH(1, ('Cleaned Data'!$A$3:$A$374 = 'Q1 CPI Basket Contri Analysis'!$C$4)* ('Cleaned Data'!$B$3:$B$374 ='Q1 CPI Basket Contri Analysis'!$B$2)* ('Cleaned Data'!$C$3:$C$374 = 'Q1 CPI Basket Contri Analysis'!$B$3), 0),MATCH($A21,'Cleaned Data'!$D$1:$AD$1,0))} -> 190.8 | D21: {=INDEX('Cleaned Data'!$D$3:$AD$374, MATCH(1, ('Cleaned Data'!$A$3:$A$374 = $D$4)* ('Cleaned Data'!$B$3:$B$374 ='Q1 CPI Basket Contri Analysis'!$B$2)* ('Cleaned Data'!$C$3:$C$374 = 'Q1 CPI Basket Contri Analysis'!$B$3), 0),MATCH($A21,'Cleaned Data'!$D$1:$AD$1,0))} -> 179.3 | E21: {=INDEX('Cleaned Data'!$D$3:$AD$374, MATCH(1, ('Cleaned Data'!$A$3:$A$374 = $E$4)* ('Cleaned Data'!$B$3:$B$374 ='Q1 CPI Basket Contri Analysis'!$B$2)* ('Cleaned Data'!$C$3:$C$374 = 'Q1 CPI Basket Contri Analysis'!$B$3), 0),MATCH($A21,'Cleaned Data'!$D$1:$AD$1,0))} -> 186.2
... A30: Miscellaneous | B30: =VLOOKUP($A30,'[1]EDA and Analysis1'!$A:$B,2,0) -> Services and Miscellaneous | C30: {=INDEX('Cleaned Data'!$D$3:$AD$374, MATCH(1, ('Cleaned Data'!$A$3:$A$374 = 'Q1 CPI Basket Contri Analysis'!$C$4)* ('Cleaned Data'!$B$3:$B$374 ='Q1 CPI Basket Contri Analysis'!$B$2)* ('Cleaned Data'!$C$3:$C$374 = 'Q1 CPI Basket Contri Analysis'!$B$3), 0),MATCH($A30,'Cleaned Data'!$D$1:$AD$1,0))} -> 179.5 | D30: {=INDEX('Cleaned Data'!$D$3:$AD$374, MATCH(1, ('Cleaned Data'!$A$3:$A$374 = $D$4)* ('Cleaned Data'!$B$3:$B$374 ='Q1 CPI Basket Contri Analysis'!$B$2)* ('Cleaned Data'!$C$3:$C$374 = 'Q1 CPI Basket Contri Analysis'!$B$3), 0),MATCH($A30,'Cleaned Data'!$D$1:$AD$1,0))} -> 171.6 | E30: {=INDEX('Cleaned Data'!$D$3:$AD$374, MATCH(1, ('Cleaned Data'!$A$3:$A$374 = $E$4)* ('Cleaned Data'!$B$3:$B$374 ='Q1 CPI Basket Contri Analysis'!$B$2)* ('Cleaned Data'!$C$3:$C$374 = 'Q1 CPI Basket Contri Analysis'!$B$3), 0),MATCH($A30,'Cleaned Data'!$D$1:$AD$1,0))} -> 175.7

Sheet Q2 Y-O-Y CPI Trend
C3: Sector | D3: Rural+Urban
C4: Year | D4: Start Month | E4: End Month | F4: Starting GI Index | G4: Ending GI Index | H4: CPI Inflation
C5: 2017 | D5: January | E5: December | F5: {=INDEX('Cleaned Data'!$AD$3:$AD$374, MATCH(1, ('Cleaned Data'!$A$3:$A$374=$D$3)* ('Cleaned Data'!$B$3:$B$374=$C5)* ('Cleaned Data'!$C$3:$C$374=$D5), 0))} -> 130.3 | G5: {=INDEX('Cleaned Data'!$AD$3:$AD$374, MATCH(1, ('Cleaned Data'!$A$3:$A$374=$D$3)* ('Cleaned Data'!$B$3:$B$374=$C5)* ('Cleaned Data'!$C$3:$C$374=$E5), 0))} -> 137.2 | H5: =(G5-F5)/F5 -> 0.05295472
C6: 2018 | D6: January | E6: December | F6: {=INDEX('Cleaned Data'!$AD$3:$AD$374, MATCH(1, ('Cleaned Data'!$A$3:$A$374=$D$3)* ('Cleaned Data'!$B$3:$B$374=$C6)* ('Cleaned Data'!$C$3:$C$374=$D6), 0))} -> 136.9 | G6: {=INDEX('Cleaned Data'!$AD$3:$AD$374, MATCH(1, ('Cleaned Data'!$A$3:$A$374=$D$3)* ('Cleaned Data'!$B$3:$B$374=$C6)* ('Cleaned Data'!$C$3:$C$374=$E6), 0))} -> 140.1 | H6: =(G6-F6)/F6 -> 0.023374726
C7: 2019 | D7: January | E7: December | F7: {=INDEX('Cleaned Data'!$AD$3:$AD$374, MATCH(1, ('Cleaned Data'!$A$3:$A$374=$D$3)* ('Cleaned Data'!$B$3:$B$374=$C7)* ('Cleaned Data'!$C$3:$C$374=$D7), 0))} -> 139.6 | G7: {=INDEX('Cleaned Data'!$AD$3:$AD$374, MATCH(1, ('Cleaned Data'!$A$3:$A$374=$D$3)* ('Cleaned Data'!$B$3:$B$374=$C7)* ('Cleaned Data'!$C$3:$C$374=$E7), 0))} -> 150.4 | H7: =(G7-F7)/F7 -> 0.077363897
C8: 2020 | D8: January | E8: December | F8: {=INDEX('Cleaned Data'!$AD$3:$AD$374, MATCH(1, ('Cleaned Data'!$A$3:$A$374=$D$3)* ('Cleaned Data'!$B$3:$B$374=$C8)* ('Cleaned Data'!$C$3:$C$374=$D8), 0))} -> 150.2 | G8: {=INDEX('Cleaned Data'!$AD$3:$AD$374, MATCH(1, ('Cleaned Data'!$A$3:$A$374=$D$3)* ('Cleaned Data'!$B$3:$B$374=$C8)* ('Cleaned Data'!$C$3:$C$374=$E8), 0))} -> 158.9 | H8: =(G8-F8)/F8 -> 0.05792277
C9: 2021 | D9: January | E9: December | F9: {=INDEX('Cleaned Data'!$AD$3:$AD$374, MATCH(1, ('Cleaned Data'!$A$3:$A$374=$D$3)* ('Cleaned Data'!$B$3:$B$374=$C9)* ('Cleaned Data'!$C$3:$C$374=$D9), 0))} -> 157.3 | G9: {=INDEX('Cleaned Data'!$AD$3:$AD$374, MATCH(1, ('Cleaned Data'!$A$3:$A$374=$D$3)* ('Cleaned Data'!$B$3:$B$374=$C9)* ('Cleaned Data'!$C$3:$C$374=$E9), 0))} -> 166.2 | H9: =(G9-F9)/F9 -> 0.056579784
C10: 2022 | D10: January | E10: December | F10: {=INDEX('Cleaned Data'!$AD$3:$AD$374, MATCH(1, ('Cleaned Data'!$A$3:$A$374=$D$3)* ('Cleaned Data'!$B$3:$B$374=$C10)* ('Cleaned Data'!$C$3:$C$374=$D10), 0))} -> 165.7 | G10: {=INDEX('Cleaned Data'!$AD$3:$AD$374, MATCH(1, ('Cleaned Data'!$A$3:$A$374=$D$3)* ('Cleaned Data'!$B$3:$B$374=$C10)* ('Cleaned Data'!$C$3:$C$374=$E10), 0))} -> 175.7 | H10: =(G10-F10)/F10 -> 0.06035003
C11: 2023 | D11: January | E11: May | F11: {=INDEX('Cleaned Data'!$AD$3:$AD$374, MATCH(1, ('Cleaned Data'!$A$3:$A$374=$D$3)* ('Cleaned Data'!$B$3:$B$374=$C11)* ('Cleaned Data'!$C$3:$C$374=$D11), 0))} -> 176.5 | G11: {=INDEX('Cleaned Data'!$AD$3:$AD$374, MATCH(1, ('Cleaned Data'!$A$3:$A$374=$D$3)* ('Cleaned Data'!$B$3:$B$374=$C11)* ('Cleaned Data'!$C$3:$C$374=$E11), 0))} -> 179.1 | H11: =(G11-F11)/F11 -> 0.014730878
C14: Year | D14: CPI Inflation %
C15: 2016 | D15: 0
C16: 2017 | D16: 0.05295472
C17: 2018 | D17: 0.023374726
C18: 2019 | D18: 0.077363897
C19: 2020 | D19: 0.05792277
C20: 2021 | D20: 0.056579784
C21: 2022 | D21: 0.06035003
C22: 2023 | D22: 0.014730878

Sheet Q3 MOM Food Inflation Analysis
C4: Year | D4: 2022 | Q4: M-O-M Inflation
B6: Sector | C6: Rural | Q6: Rural
B7: Categories | C7: May | D7: June | E7: July | F7: August | G7: September | H7: October | I7: November | J7: December | K7: January | L7: February | M7: March | N7: April | O7: May | Q7: 44713 | R7: 44743 | S7: 44774 | T7: 44805 | U7: 44835 | V7: 44866 | W7: 44896 | X7: 44927 | Y7: 44958 | Z7: 44986 | AA7: 45017 | AB7: 45047 | AC7: 12 Month Inflation
A8: Basic Food Items | B8: Cereals and products | C8: 152.9 | D8: 153.8 | E8: 155.2 | F8: 159.5 | G8: 162.9 | H8: 164.7 | I8: 166.9 | J8: 168.8 | K8: 174 | L8: 174.2 | M8: 174.3 | N8: 173.3 | O8: 173.2 | Q8: =(D8-C8)/C8 -> 0.0058862001 | R8: =(E8-D8)/D8 -> 0.0091027308 | S8: =(F8-E8)/E8 -> 0.027706186 | T8: =(G8-F8)/F8 -> 0.021316614 | U8: =(H8-G8)/G8 -> 0.011049724 | V8: =(I8-H8)/H8 -> 0.01335762 | W8: =(J8-I8)/I8 -> 0.011384062 | X8: =(K8-J8)/J8 -> 0.030805687 | ... AB8: =(O8-N8)/N8 -> -0.00057703405 | AC8: =($O8-$C8)/$C8 -> 0.13276651
B9: Meat and fish | C9: 214.7 | D9: 217.2 | E9: 210.8 | F9: 204.1 | G9: 206.7 | H9: 208.8 | I9: 207.2 | J9: 206.9 | K9: 208.3 | L9: 205.2 | M9: 205.2 | N9: 206.9 | O9: 211.5 | Q9: =(D9-C9)/C9 -> 0.011644155 | R9: =(E9-D9)/D9 -> -0.02946593 | S9: =(F9-E9)/E9 -> -0.031783681 | T9: =(G9-F9)/F9 -> 0.012738854 | U9: =(H9-G9)/G9 -> 0.010159652 | V9: =(I9-H9)/H9 -> -0.0076628352 | W9: =(J9-I9)/I9 -> -0.0014478764 | X9: =(K9-J9)/J9 -> 0.0067665539 | ... AB9: =(O9-N9)/N9 -> 0.022232963 | AC9: =($O9-$C9)/$C9 -> -0.014904518
B10: Egg | C10: 161.4 | D10: 169.6 | E10: 174.3 | F10: 168.3 | G10: 169 | H10: 170.3 | I10: 180.2 | J10: 189.1 | K10: 192.9 | L10: 173.9 | M10: 173.9 | N10: 167.9 | O10: 171 | Q10: =(D10-C10)/C10 -> 0.050805452 | R10: =(E10-D10)/D10 -> 0.027712264 | S10: =(F10-E10)/E10 -> -0.034423408 | T10: =(G10-F10)/F10 -> 0.0041592395 | U10: =(H10-G10)/G10 -> 0.0076923077 | V10: =(I10-H10)/H10 -> 0.058132707 | W10: =(J10-I10)/I10 -> 0.049389567 | X10: =(K10-J10)/J10 -> 0.020095188 | ... AB10: =(O10-N10)/N10 -> 0.018463371 | AC10: =($O10-$C10)/$C10 -> 0.059479554
B11: Milk and products | C11: 164.6 | D11: 165.4 | E11: 166.3 | F11: 167.9 | G11: 169.5 | H11: 170.9 | I11: 172.3 | J11: 173.4 | K11: 174.3 | L11: 177 | M11: 177 | N11: 178.2 | O11: 179.6 | Q11: =(D11-C11)/C11 -> 0.0048602673 | R11: =(E11-D11)/D11 -> 0.0054413543 | S11: =(F11-E11)/E11 -> 0.0096211666 | T11: =(G11-F11)/F11 -> 0.0095294818 | U11: =(H11-G11)/G11 -> 0.008259587 | V11: =(I11-H11)/H11 -> 0.0081919251 | W11: =(J11-I11)/I11 -> 0.0063842136 | X11: =(K11-J11)/J11 -> 0.0051903114 | ... AB11: =(O11-N11)/N11 -> 0.0078563412 | AC11: =($O11-$C11)/$C11 -> 0.091130012
B12: Oils and fats | C12: 209.9 | D12: 208.1 | E12: 202.2 | F12: 198.1 | G12: 194.1 | H12: 191.6 | I12: 194 | J12: 193.9 | K12: 192.6 | L12: 183.4 | M12: 183.3 | N12: 178.5 | O12: 173.3 | Q12: =(D12-C12)/C12 -> -0.0085755121 | R12: =(E12-D12)/D12 -> -0.028351754 | S12: =(F12-E12)/E12 -> -0.020276954 | T12: =(G12-F12)/F12 -> -0.020191822 | U12: =(H12-G12)/G12 -> -0.012879959 | V12: =(I12-H12)/H12 -> 0.012526096 | W12: =(J12-I12)/I12 -> -0.00051546392 | X12: =(K12-J12)/J12 -> -0.0067044868 | ... AB12: =(O12-N12)/N12 -> -0.029131653 | AC12: =($O12-$C12)/$C12 -> -0.17436875
B13: Fruits | C13: 168 | D13: 165.8 | E13: 169.6 | F13: 169.2 | G13: 164.1 | H13: 162.2 | I13: 159.1 | J13: 156.7 | K13: 156.3 | L13: 167.2 | M13: 167.2 | N13: 173.7 | O13: 169 | Q13: =(D13-C13)/C13 -> -0.013095238 | R13: =(E13-D13)/D13 -> 0.02291918 | S13: =(F13-E13)/E13 -> -0.0023584906 | T13: =(G13-F13)/F13 -> -0.030141844 | U13: =(H13-G13)/G13 -> -0.011578306 | V13: =(I13-H13)/H13 -> -0.019112207 | W13: =(J13-I13)/I13 -> -0.015084852 | X13: =(K13-J13)/J13 -> -0.0025526484 | ... AB13: =(O13-N13)/N13 -> -0.027058146 | AC13: =($O13-$C13)/$C13 -> 0.005952381
B14: Vegetables | C14: 160.4 | D14: 167.3 | E14: 168.6 | F14: 173.1 | G14: 176.9 | H14: 184.8 | I14: 171.6 | J14: 150.2 | K14: 142.9 | L14: 140.9 | M14: 140.9 | N14: 142.8 | O14: 148.7 | Q14: =(D14-C14)/C14 -> 0.043017456 | R14: =(E14-D14)/D14 -> 0.0077704722 | S14: =(F14-E14)/E14 -> 0.026690391 | T14: =(G14-F14)/F14 -> 0.021952629 | U14: =(H14-G14)/G14 -> 0.044657999 | V14: =(I14-H14)/H14 -> -0.071428571 | W14: =(J14-I14)/I14 -> -0.12470862 | X14: =(K14-J14)/J14 -> -0.048601864 | ... AB14: =(O14-N14)/N14 -> 0.041316527 | AC14: =($O14-$C14)/$C14 -> -0.072942643
B15: Pulses and products | C15: 165 | D15: 164.6 | E15: 164.4 | F15: 167.1 | G15: 169 | H15: 169.7 | I15: 170.2 | J15: 170.5 | K15: 170.7 | L15: 170.4 | M15: 170.5 | N15: 172.8 | O15: 174.9 | Q15: =(D15-C15)/C15 -> -0.0024242424 | R15: =(E15-D15)/D15 -> -0.0012150668 | S15: =(F15-E15)/E15 -> 0.016423358 | T15: =(G15-F15)/F15 -> 0.011370437 | U15: =(H15-G15)/G15 -> 0.0041420118 | V15: =(I15-H15)/H15 -> 0.002946376 | W15: =(J15-I15)/I15 -> 0.0017626322 | X15: =(K15-J15)/J15 -> 0.0011730205 | ... AB15: =(O15-N15)/N15 -> 0.012152778 | AC15: =($O15-$C15)/$C15 -> 0.06
B16: Spices | C16: 186.6 | D16: 188.9 | E16: 191.8 | F16: 195.6 | G16: 199.1 | H16: 201.6 | I16: 204.8 | J16: 207.5 | K16: 210.5 | L16: 212.1 | M16: 212.1 | N16: 215.5 | O16: 221 | Q16: =(D16-C16)/C16 -> 0.012325831 | R16: =(E16-D16)/D16 -> 0.015352038 | S16: =(F16-E16)/E16 -> 0.019812304 | T16: =(G16-F16)/F16 -> 0.017893661 | U16: =(H16-G16)/G16 -> 0.012556504 | V16: =(I16-H16)/H16 -> 0.015873016 | W16: =(J16-I16)/I16 -> 0.013183594 | X16: =(K16-J16)/J16 -> 0.014457831 | ... AB16: =(O16-N16)/N16 -> 0.025522042 | AC16: =($O16-$C16)/$C16 -> 0.18435155
A17: Other Food and Intoxicants | B17: Sugar and Confectionery | C17: 118.9 | D17: 119.1 | E17: 119.2 | F17: 120.2 | G17: 120.8 | H17: 121.1 | I17: 121.5 | J17: 121.2 | K17: 120.3 | L17: 119.1 | M17: 119.1 | N17: 120.4 | O17: 121.9 | Q17: =(D17-C17)/C17 -> 0.0016820858 | R17: =(E17-D17)/D17 -> 0.00083963056 | S17: =(F17-E17)/E17 -> 0.0083892617 | T17: =(G17-F17)/F17 -> 0.0049916805 | U17: =(H17-G17)/G17 -> 0.0024834437 | V17: =(I17-H17)/H17 -> 0.0033030553 | W17: =(J17-I17)/I17 -> -0.0024691358 | X17: =(K17-J17)/J17 -> -0.0074257426 | ... AB17: =(O17-N17)/N17 -> 0.012458472 | AC17: =($O17-$C17)/$C17 -> 0.025231287
B18: Non-alcoholic beverages | C18: 173.2 | D18: 174.2 | E18: 174.5 | F18: 174.8 | G18: 175.4 | H18: 175.8 | I18: 176.4 | J18: 176.8 | K18: 176.9 | L18: 177.6 | M18: 177.6 | N18: 178.2 | O18: 178.7 | Q18: =(D18-C18)/C18 -> 0.0057736721 | R18: =(E18-D18)/D18 -> 0.0017221584 | S18: =(F18-E18)/E18 -> 0.0017191977 | T18: =(G18-F18)/F18 -> 0.0034324943 | U18: =(H18-G18)/G18 -> 0.0022805017 | V18: =(I18-H18)/H18 -> 0.0034129693 | W18: =(J18-I18)/I18 -> 0.0022675737 | X18: =(K18-J18)/J18 -> 0.00056561086 | ... AB18: =(O18-N18)/N18 -> 0.0028058361 | AC18: =($O18-$C18)/$C18 -> 0.031755196
B19: Prepared meals, snacks, sweets, etc. | C19: 180.4 | D19: 181.9 | E19: 183.1 | F19: 184 | G19: 184.8 | H19: 185.6 | I19: 186.9 | J19: 187.7 | K19: 188.5 | L19: 189.9 | M19: 189.9 | N19: 190.5 | O19: 191.1 | Q19: =(D19-C19)/C19 -> 0.0083148559 | R19: =(E19-D19)/D19 -> 0.0065970313 | S19: =(F19-E19)/E19 -> 0.0049153468 | T19: =(G19-F19)/F19 -> 0.0043478261 | U19: =(H19-G19)/G19 -> 0.0043290043 | V19: =(I19-H19)/H19 -> 0.0070043103 | W19: =(J19-I19)/I19 -> 0.0042803638 | X19: =(K19-J19)/J19 -> 0.0042621204 | ... AB19: =(O19-N19)/N19 -> 0.0031496063 | AC19: =($O19-$C19)/$C19 -> 0.059312639
B20: Food and beverages | C20: 170.8 | D20: 172.4 | E20: 172.5 | F20: 173.9 | G20: 175.5 | H20: 177.4 | I20: 176.6 | J20: 174.4 | K20: 175 | L20: 174.8 | M20: 174.8 | N20: 175.5 | O20: 176.8 | Q20: =(D20-C20)/C20 -> 0.0093676815 | R20: =(E20-D20)/D20 -> 0.0005800464 | S20: =(F20-E20)/E20 -> 0.008115942 | T20: =(G20-F20)/F20 -> 0.0092006901 | U20: =(H20-G20)/G20 -> 0.010826211 | V20: =(I20-H20)/H20 -> -0.0045095829 | W20: =(J20-I20)/I20 -> -0.012457531 | X20: =(K20-J20)/J20 -> 0.003440367 | ... AB20: =(O20-N20)/N20 -> 0.0074074074 | AC20: =($O20-$C20)/$C20 -> 0.035128806
B21: Pan, tobacco, and intoxicants | C21: 192.9 | D21: 192.9 | E21: 193.2 | F21: 193.7 | G21: 194.5 | H21: 194.9 | I21: 195.5 | J21: 195.9 | K21: 196.9 | L21: 198.3 | M21: 198.4 | N21: 199.5 | O21: 199.9 | Q21: =(D21-C21)/C21 -> 0 | R21: =(E21-D21)/D21 -> 0.00155521 | S21: =(F21-E21)/E21 -> 0.0025879917 | T21: =(G21-F21)/F21 -> 0.0041300981 | U21: =(H21-G21)/G21 -> 0.0020565553 | V21: =(I21-H21)/H21 -> 0.0030785018 | W21: =(J21-I21)/I21 -> 0.0020460358 | X21: =(K21-J21)/J21 -> 0.0051046452 | ... AB21: =(O21-N21)/N21 -> 0.0020050125 | AC21: =($O21-$C21)/$C21 -> 0.036288232
B24: Year | C24: 44682 | D24: 44713 | E24: 44743 | F24: 44774 | G24: 44805 | H24: 44835 | I24: 44866 | J24: 44896 | K24: 44927 | L24: 44958 | M24: 44986 | N24: 45017 | O24: 45047
B25: Basic Food Items | C25: =SUM(C8:C16) -> 1583.5 | D25: =SUM(D8:D16) -> 1600.7 | E25: =SUM(E8:E16) -> 1603.2 | F25: =SUM(F8:F16) -> 1602.9 | G25: =SUM(G8:G16) -> 1611.3 | H25: =SUM(H8:H16) -> 1624.6 | I25: =SUM(I8:I16) -> 1626.3 | J25: =SUM(J8:J16) -> 1617 | ... O25: =SUM(O8:O16) -> 1622.2
C26: Inflation M-O-M | D26: =(D25-C25)/C25 -> 0.010862015 | E26: =(E25-D25)/D25 -> 0.0015618167 | F26: =(F25-E25)/E25 -> -0.00018712575 | G26: =(G25-F25)/F25 -> 0.0052405016 | H26: =(H25-G25)/G25 -> 0.0082542047 | I26: =(I25-H25)/H25 -> 0.0010464114 | J26: =(J25-I25)/I25 -> -0.0057185021 | K26: =(K25-J25)/J25 -> 0.0034013605 | ... O26: =(O25-N25)/N25 -> 0.0078280318
B28: Other Food and Intoxicants | C28: =SUM(C17:C21) -> 836.2 | D28: =SUM(D17:D21) -> 840.5 | E28: =SUM(E17:E21) -> 842.5 | F28: =SUM(F17:F21) -> 846.6 | G28: =SUM(G17:G21) -> 851 | H28: =SUM(H17:H21) -> 854.8 | I28: =SUM(I17:I21) -> 856.9 | J28: =SUM(J17:J21) -> 856 | ... O28: =SUM(O17:O21) -> 868.4
C29: Inflation M-O-M | D29: =(D28-C28)/C28 -> 0.0051423105 | E29: =(E28-D28)/D28 -> 0.002379536 | F29: =(F28-E28)/E28 -> 0.0048664688 | G29: =(G28-F28)/F28 -> 0.0051972596 | H29: =(H28-G28)/G28 -> 0.0044653349 | I29: =(I28-H28)/H28 -> 0.002456715 | J29: =(J28-I28)/I28 -> -0.0010502976 | K29: =(K28-J28)/J28 -> 0.0018691589 | ... O29: =(O28-N28)/N28 -> 0.0049762759
B32: Sector | C32: Urban | Q32: Urban
A33: Basic Food Items | B33: Categories | C33: May | D33: June | E33: July | F33: August | G33: September | H33: October | I33: November | J33: December | K33: January | L33: February | M33: March | N33: April | O33: May | Q33: 44713 | R33: 44743 | S33: 44774 | T33: 44805 | U33: 44835 | V33: 44866 | W33: 44896 | X33: 44927 | Y33: 44958 | Z33: 44986 | AA33: 45017 | AB33: 45047 | AC33: 12 Month Inflation
B34: Cereals and products | C34: 156.7 | D34: 157.5 | E34: 159.3 | F34: 162.1 | G34: 164.9 | H34: 166.4 | I34: 168.4 | J34: 170.2 | K34: 173.3 | L34: 174.7 | M34: 174.7 | N34: 174.8 | O34: 174.7 | Q34: =(D34-C34)/C34 -> 0.0051052967 | R34: =(E34-D34)/D34 -> 0.011428571 | S34: =(F34-E34)/E34 -> 0.017576899 | T34: =(G34-F34)/F34 -> 0.017273288 | U34: =(H34-G34)/G34 -> 0.0090964221 | V34: =(I34-H34)/H34 -> 0.012019231 | W34: =(J34-I34)/I34 -> 0.010688836 | X34: =(K34-J34)/J34 -> 0.018213866 | ... AB34: =(O34-N34)/N34 -> -0.00057208238 | AC34: =($O34-$C34)/$C34 -> 0.11486918
B35: Meat and fish | C35: 221.2 | D35: 223.4 | E35: 217.1 | F35: 210.9 | G35: 213.7 | H35: 214.9 | I35: 213.4 | J35: 212.9 | K35: 215.2 | L35: 212.2 | M35: 212.2 | N35: 213.7 | O35: 219.4 | Q35: =(D35-C35)/C35 -> 0.0099457505 | R35: =(E35-D35)/D35 -> -0.028200537 | S35: =(F35-E35)/E35 -> -0.028558268 | T35: =(G35-F35)/F35 -> 0.013276434 | U35: =(H35-G35)/G35 -> 0.0056153486 | V35: =(I35-H35)/H35 -> -0.0069799907 | W35: =(J35-I35)/I35 -> -0.0023430178 | X35: =(K35-J35)/J35 -> 0.010803194 | ... AB35: =(O35-N35)/N35 -> 0.026672906 | AC35: =($O35-$C35)/$C35 -> -0.0081374322
B36: Egg | C36: 164.1 | D36: 172.8 | E36: 176.6 | F36: 170.6 | G36: 170.9 | H36: 171.9 | I36: 183.2 | J36: 191.9 | K36: 197 | L36: 177.2 | M36: 177.2 | N36: 172.4 | O36: 176.7 | Q36: =(D36-C36)/C36 -> 0.053016453 | R36: =(E36-D36)/D36 -> 0.021990741 | S36: =(F36-E36)/E36 -> -0.033975085 | T36: =(G36-F36)/F36 -> 0.0017584994 | U36: =(H36-G36)/G36 -> 0.0058513751 | V36: =(I36-H36)/H36 -> 0.065735893 | W36: =(J36-I36)/I36 -> 0.047489083 | X36: =(K36-J36)/J36 -> 0.026576342 | ... AB36: =(O36-N36)/N36 -> 0.024941995 | AC36: =($O36-$C36)/$C36 -> 0.07678245
B37: Milk and products | C37: 165.4 | D37: 166.4 | E37: 167.1 | F37: 168.4 | G37: 170.1 | H37: 171 | I37: 172.3 | J37: 173.9 | K37: 175.2 | L37: 177.9 | M37: 177.9 | N37: 178.8 | O37: 179.4 | Q37: =(D37-C37)/C37 -> 0.0060459492 | R37: =(E37-D37)/D37 -> 0.0042067308 | S37: =(F37-E37)/E37 -> 0.0077797726 | T37: =(G37-F37)/F37 -> 0.010095012 | U37: =(H37-G37)/G37 -> 0.0052910053 | V37: =(I37-H37)/H37 -> 0.0076023392 | W37: =(J37-I37)/I37 -> 0.0092861288 | X37: =(K37-J37)/J37 -> 0.0074755607 | ... AB37: =(O37-N37)/N37 -> 0.0033557047 | AC37: =($O37-$C37)/$C37 -> 0.084643289
B38: Oils and fats | C38: 189.5 | D38: 188.6 | E38: 184.8 | F38: 182.5 | G38: 179.3 | H38: 177.7 | I38: 180 | J38: 179.1 | K38: 178 | L38: 172.2 | M38: 172.2 | N38: 168.7 | O38: 164.4 | Q38: =(D38-C38)/C38 -> -0.0047493404 | R38: =(E38-D38)/D38 -> -0.020148462 | S38: =(F38-E38)/E38 -> -0.012445887 | T38: =(G38-F38)/F38 -> -0.017534247 | U38: =(H38-G38)/G38 -> -0.0089235917 | V38: =(I38-H38)/H38 -> 0.012943163 | W38: =(J38-I38)/I38 -> -0.005 | X38: =(K38-J38)/J38 -> -0.0061418202 | ... AB38: =(O38-N38)/N38 -> -0.025489034 | AC38: =($O38-$C38)/$C38 -> -0.13245383
B39: Fruits | C39: 174.5 | D39: 174.1 | E39: 179.5 | F39: 177.1 | G39: 167.5 | H39: 165.7 | I39: 162.6 | J39: 159.5 | K39: 160.5 | L39: 172.1 | M39: 172.1 | N39: 179.2 | O39: 175.8 | Q39: =(D39-C39)/C39 -> -0.0022922636 | R39: =(E39-D39)/D39 -> 0.031016657 | S39: =(F39-E39)/E39 -> -0.013370474 | T39: =(G39-F39)/F39 -> -0.054206663 | U39: =(H39-G39)/G39 -> -0.010746269 | V39: =(I39-H39)/H39 -> -0.018708509 | W39: =(J39-I39)/I39 -> -0.019065191 | X39: =(K39-J39)/J39 -> 0.0062695925 | ... AB39: =(O39-N39)/N39 -> -0.018973214 | AC39: =($O39-$C39)/$C39 -> 0.0074498567
B40: Vegetables | C40: 203.2 | D40: 211.5 | E40: 208.5 | F40: 213.1 | G40: 220.8 | H40: 228.6 | I40: 205.5 | J40: 178.7 | K40: 175.3 | L40: 175.8 | M40: 175.9 | N40: 179.9 | O40: 185 | Q40: =(D40-C40)/C40 -> 0.040846457 | R40: =(E40-D40)/D40 -> -0.014184397 | S40: =(F40-E40)/E40 -> 0.02206235 | T40: =(G40-F40)/F40 -> 0.036133271 | U40: =(H40-G40)/G40 -> 0.035326087 | V40: =(I40-H40)/H40 -> -0.10104987 | W40: =(J40-I40)/I40 -> -0.13041363 | X40: =(K40-J40)/J40 -> -0.019026301 | ... AB40: =(O40-N40)/N40 -> 0.028349083 | AC40: =($O40-$C40)/$C40 -> -0.089566929
B41: Pulses and products | C41: 164.1 | D41: 163.6 | E41: 164 | F41: 167.3 | G41: 169.2 | H41: 169.9 | I41: 171 | J41: 171.3 | K41: 171.2 | L41: 172.2 | M41: 172.2 | N41: 174.7 | O41: 176.9 | Q41: =(D41-C41)/C41 -> -0.0030469226 | R41: =(E41-D41)/D41 -> 0.0024449878 | S41: =(F41-E41)/E41 -> 0.020121951 | T41: =(G41-F41)/F41 -> 0.011356844 | U41: =(H41-G41)/G41 -> 0.0041371158 | V41: =(I41-H41)/H41 -> 0.0064743967 | W41: =(J41-I41)/I41 -> 0.001754386 | X41: =(K41-J41)/J41 -> -0.00058377116 | ... AB41: =(O41-N41)/N41 -> 0.012593017 | AC41: =($O41-$C41)/$C41 -> 0.078001219
B42: Spices | C42: 181.4 | D42: 183.5 | E42: 186.3 | F42: 189.7 | G42: 193.6 | H42: 196.4 | I42: 198.8 | J42: 200.5 | K42: 204.3 | L42: 204.8 | M42: 204.8 | N42: 207.8 | O42: 211.9 | Q42: =(D42-C42)/C42 -> 0.011576626 | R42: =(E42-D42)/D42 -> 0.015258856 | S42: =(F42-E42)/E42 -> 0.018250134 | T42: =(G42-F42)/F42 -> 0.020558777 | U42: =(H42-G42)/G42 -> 0.01446281 | V42: =(I42-H42)/H42 -> 0.012219959 | W42: =(J42-I42)/I42 -> 0.0085513078 | X42: =(K42-J42)/J42 -> 0.018952618 | ... AB42: =(O42-N42)/N42 -> 0.01973051 | AC42: =($O42-$C42)/$C42 -> 0.16813671
A43: Other Food and Intoxicants | B43: Sugar and Confectionery | C43: 121.2 | D43: 121.4 | E43: 121.5 | F43: 122.2 | G43: 123.1 | H43: 123.4 | I43: 123.4 | J43: 123.1 | K43: 122.7 | L43: 121.9 | M43: 121.9 | N43: 123.1 | O43: 124.2 | Q43: =(D43-C43)/C43 -> 0.001650165 | R43: =(E43-D43)/D43 -> 0.00082372323 | S43: =(F43-E43)/E43 -> 0.0057613169 | T43: =(G43-F43)/F43 -> 0.0073649755 | U43: =(H43-G43)/G43 -> 0.0024370431 | V43: =(I43-H43)/H43 -> 0 | W43: =(J43-I43)/I43 -> -0.0024311183 | X43: =(K43-J43)/J43 -> -0.0032493907 | ... AB43: =(O43-N43)/N43 -> 0.0089358245 | AC43: =($O43-$C43)/$C43 -> 0.024752475
B44: Non-alcoholic beverages | C44: 158.5 | D44: 159.1 | E44: 159.8 | F44: 160.5 | G44: 161.1 | H44: 161.6 | I44: 162.1 | J44: 162.8 | K44: 163.7 | L44: 164.9 | M44: 164.9 | N44: 165.5 | O44: 165.9 | Q44: =(D44-C44)/C44 -> 0.003785489 | R44: =(E44-D44)/D44 -> 0.0043997486 | S44: =(F44-E44)/E44 -> 0.0043804756 | T44: =(G44-F44)/F44 -> 0.0037383178 | U44: =(H44-G44)/G44 -> 0.0031036623 | V44: =(I44-H44)/H44 -> 0.0030940594 | W44: =(J44-I44)/I44 -> 0.004318322 | X44: =(K44-J44)/J44 -> 0.0055282555 | ... AB44: =(O44-N44)/N44 -> 0.0024169184 | AC44: =($O44-$C44)/$C44 -> 0.046687697
B45: Prepared meals, snacks, sweets, etc. | C45: 184.9 | D45: 186.3 | E45: 187.7 | F45: 188.9 | G45: 190.4 | H45: 191.5 | I45: 192.4 | J45: 193.3 | K45: 194.3 | L45: 196.6 | M45: 196.6 | N45: 197 | O45: 197.7 | Q45: =(D45-C45)/C45 -> 0.0075716604 | R45: =(E45-D45)/D45 -> 0.0075147611 | S45: =(F45-E45)/E45 -> 0.0063931806 | T45: =(G45-F45)/F45 -> 0.0079407094 | U45: =(H45-G45)/G45 -> 0.0057773109 | V45: =(I45-H45)/H45 -> 0.0046997389 | W45: =(J45-I45)/I45 -> 0.0046777547 | X45: =(K45-J45)/J45 -> 0.0051733057 | ... AB45: =(O45-N45)/N45 -> 0.0035532995 | AC45: =($O45-$C45)/$C45 -> 0.069226609
B46: Food and beverages | C46: 177.5 | D46: 179.3 | E46: 179.4 | F46: 180.4 | G46: 181.8 | H46: 183.3 | I46: 181.3 | J46: 178.6 | K46: 179.5 | L46: 180.7 | M46: 180.8 | N46: 182.1 | O46: 183.1 | Q46: =(D46-C46)/C46 -> 0.010140845 | R46: =(E46-D46)/D46 -> 0.00055772448 | S46: =(F46-E46)/E46 -> 0.005574136 | T46: =(G46-F46)/F46 -> 0.0077605322 | U46: =(H46-G46)/G46 -> 0.0082508251 | V46: =(I46-H46)/H46 -> -0.010911075 | W46: =(J46-I46)/I46 -> -0.014892443 | X46: =(K46-J46)/J46 -> 0.0050391937 | ... AB46: =(O46-N46)/N46 -> 0.0054914882 | AC46: =($O46-$C46)/$C46 -> 0.031549296
B47: Pan, tobacco, and intoxicants | C47: 197.5 | D47: 198.3 | E47: 198.6 | F47: 198.7 | G47: 199.7 | H47: 200.1 | I47: 200.6 | J47: 201.1 | K47: 201.6 | L47: 202.7 | M47: 202.7 | N47: 203.5 | O47: 204.2 | Q47: =(D47-C47)/C47 -> 0.0040506329 | R47: =(E47-D47)/D47 -> 0.0015128593 | S47: =(F47-E47)/E47 -> 0.00050352467 | T47: =(G47-F47)/F47 -> 0.0050327126 | U47: =(H47-G47)/G47 -> 0.0020030045 | V47: =(I47-H47)/H47 -> 0.0024987506 | W47: =(J47-I47)/I47 -> 0.0024925224 | X47: =(K47-J47)/J47 -> 0.0024863252 | ... AB47: =(O47-N47)/N47 -> 0.0034398034 | AC47: =($O47-$C47)/$C47 -> 0.033924051
B50: Year | C50: 44682 | D50: 44713 | E50: 44743 | F50: 44774 | G50: 44805 | H50: 44835 | I50: 44866 | J50: 44896 | K50: 44927 | L50: 44958 | M50: 44986 | N50: 45017 | O50: 45047
B51: Basic Food Items | C51: =SUM(C34:C42) -> 1620.1 | D51: =SUM(D34:D42) -> 1641.4 | E51: =SUM(E34:E42) -> 1643.2 | F51: =SUM(F34:F42) -> 1641.7 | G51: =SUM(G34:G42) -> 1650 | H51: =SUM(H34:H42) -> 1662.5 | I51: =SUM(I34:I42) -> 1655.2 | J51: =SUM(J34:J42) -> 1638 | ... O51: =SUM(O34:O42) -> 1664.2
...

Sheet Q4 Rural Covid Impact
B3: Covid Impact on Rural sector | V3: M-O-M Inflation Rate | AG3: Rural Y-O-Y Inflation Rate
B5: Sector | C5: Year | D5: Month | E5: Cereals and products | F5: Meat and fish | G5: Egg | H5: Milk and products | I5: Oils and fats | J5: Fruits | K5: Vegetables | L5: Pulses and products | M5: Spices | N5: Food Products Combined | O5: Fuel and light | P5: Health | Q5: Transport and communication | R5: Education | S5: Household goods and services | T5: General index | V5: Year | W5: Month | X5: Month and Year | Y5: Food Products Combined | Z5: Fuel and light | AA5: Health | AB5: Transport and communication | AC5: Education | AD5: Household goods and services | AE5: General index | AG5: Year | AH5: Food Products Combined | AI5: Fuel and light | AJ5: Health | AK5: Transport and communication | AL5: Education | AM5: Household goods and services | AN5: General index
B6: Rural | C6: 2017 | D6: March | E6: 133.6 | F6: 138.8 | G6: 128.8 | H6: 137.2 | I6: 121.6 | J6: 139.7 | K6: 119.7 | L6: 148 | M6: 135.6 | N6: =SUM(E6:M6) -> 1203 | O6: 134.2 | P6: 130.6 | Q6: 119.8 | R6: 135.2 | S6: 134.1 | T6: 132.8 | V6: 2017 | W6: March | X6: =_xlfn.CONCAT(W6," ",V6) -> March 2017 | AG6: 2017-18 | AH6: =($N6-$N17)/$N6 -> -0.033000831 | AI6: =($O6-$O17)/$O6 -> -0.061102832 | AJ6: =(P$6-P$17)/P$6 -> -0.04287902 | AK6: =(Q$6-Q$17)/Q$6 -> -0.029215359 | AL6: =(R$6-R$17)/R$6 -> -0.046597633 | AM6: =(S$6-S$17)/S$6 -> -0.043251305 | AN6: =(T$6-T$17)/T$6 -> -0.042921687
B7: Rural | C7: 2017 | D7: April | E7: 133.2 | F7: 138.7 | G7: 127.1 | H7: 137.7 | I7: 121.3 | J7: 141.8 | K7: 121.5 | L7: 144.5 | M7: 134.1 | N7: =SUM(E7:M7) -> 1199.9 | O7: 135 | P7: 131 | Q7: 119.2 | R7: 135.7 | S7: 134.3 | T7: 132.9 | V7: 2017 | W7: April | X7: =_xlfn.CONCAT(W7," ",V7) -> April 2017 | Y7: =($N7-$N6)/$N6 -> -0.0025768911 | Z7: =($O7-$O6)/$O6 -> 0.0059612519 | AA7: =($P7-$P6)/$P6 -> 0.0030627871 | AB7: =($Q7-$Q6)/$Q6 -> -0.0050083472 | AC7: =($R7-$R6)/$R6 -> 0.0036982249 | AD7: =($S7-$S6)/$S6 -> 0.0014914243 | AE7: =($T7-$T6)/$T6 -> 0.00075301205 | AG7: 2018-19 | AH7: =($N29-$N18)/$N18 -> -0.017387105 | AI7: =($O29-$O18)/$O18 -> 0.018934081 | AJ7: =(P$29-P$18)/P$18 -> 0.096561814 | AK7: =(Q$29-Q$18)/Q$18 -> 0.036918138 | AL7: =(R$29-R$18)/R$18 -> 0.089698669 | AM7: =(S$29-S$18)/S$18 -> 0.072909221 | AN7: =(T$29-T$18)/T$18 -> 0.016582552
